{
 "cells": [
  {
   "cell_type": "markdown",
   "metadata": {},
   "source": [
    "# Ref\n",
    "* style-transfer: https://colab.research.google.com/github/tensorflow/lucid/blob/master/notebooks/differentiable-parameterizations/style_transfer_2d.ipynb#scrollTo=ji42rN8sN2sb\n",
    "* cycleGAN:\n",
    "https://colab.research.google.com/github/junyanz/pytorch-CycleGAN-and-pix2pix/blob/master/CycleGAN.ipynb#scrollTo=0sp7TCT2x9dB\n",
    "* cartoonGAN:\n",
    "https://colab.research.google.com/github/TobiasSunderdiek/cartoon-gan/blob/master/CartoonGAN.ipynb#scrollTo=b342SwfIR1ur"
   ]
  },
  {
   "cell_type": "code",
   "execution_count": 1,
   "metadata": {},
   "outputs": [
    {
     "name": "stderr",
     "output_type": "stream",
     "text": [
      "WARNING: Ignoring invalid distribution -orch (c:\\users\\user\\anaconda3\\lib\\site-packages)\n",
      "WARNING: Ignoring invalid distribution -orch (c:\\users\\user\\anaconda3\\lib\\site-packages)\n",
      "WARNING: Ignoring invalid distribution -orch (c:\\users\\user\\anaconda3\\lib\\site-packages)\n",
      "    WARNING: Ignoring invalid distribution -orch (c:\\users\\user\\anaconda3\\lib\\site-packages)\n",
      "    WARNING: Ignoring invalid distribution -orch (c:\\users\\user\\anaconda3\\lib\\site-packages)\n",
      "ERROR: Cannot uninstall 'llvmlite'. It is a distutils installed project and thus we cannot accurately determine which files belong to it which would lead to only a partial uninstall.\n",
      "WARNING: Ignoring invalid distribution -orch (c:\\users\\user\\anaconda3\\lib\\site-packages)\n",
      "WARNING: Ignoring invalid distribution -orch (c:\\users\\user\\anaconda3\\lib\\site-packages)\n"
     ]
    }
   ],
   "source": [
    "!pip install -q lucid>=0.2.3"
   ]
  },
  {
   "cell_type": "code",
   "execution_count": 17,
   "metadata": {},
   "outputs": [
    {
     "name": "stdout",
     "output_type": "stream",
     "text": [
      "Requirement already satisfied: tensorflow in c:\\users\\user\\anaconda3\\lib\\site-packages (2.0.0)\n",
      "Collecting tensorflow\n",
      "  Downloading tensorflow-2.6.0-cp37-cp37m-win_amd64.whl (423.2 MB)\n",
      "Requirement already satisfied: opt-einsum~=3.3.0 in c:\\users\\user\\anaconda3\\lib\\site-packages (from tensorflow) (3.3.0)\n",
      "Collecting keras~=2.6\n",
      "  Downloading keras-2.6.0-py2.py3-none-any.whl (1.3 MB)\n",
      "Collecting grpcio<2.0,>=1.37.0\n",
      "  Downloading grpcio-1.40.0-cp37-cp37m-win_amd64.whl (3.2 MB)\n",
      "Requirement already satisfied: h5py~=3.1.0 in c:\\users\\user\\anaconda3\\lib\\site-packages (from tensorflow) (3.1.0)\n",
      "Requirement already satisfied: astunparse~=1.6.3 in c:\\users\\user\\anaconda3\\lib\\site-packages (from tensorflow) (1.6.3)\n",
      "Requirement already satisfied: keras-preprocessing~=1.1.2 in c:\\users\\user\\anaconda3\\lib\\site-packages (from tensorflow) (1.1.2)\n",
      "Collecting gast==0.4.0\n",
      "  Using cached gast-0.4.0-py3-none-any.whl (9.8 kB)\n",
      "Requirement already satisfied: typing-extensions~=3.7.4 in c:\\users\\user\\anaconda3\\lib\\site-packages (from tensorflow) (3.7.4.3)\n",
      "Requirement already satisfied: numpy~=1.19.2 in c:\\users\\user\\anaconda3\\lib\\site-packages (from tensorflow) (1.19.2)\n",
      "Requirement already satisfied: flatbuffers~=1.12.0 in c:\\users\\user\\anaconda3\\lib\\site-packages (from tensorflow) (1.12)\n",
      "Requirement already satisfied: google-pasta~=0.2 in c:\\users\\user\\anaconda3\\lib\\site-packages (from tensorflow) (0.2.0)\n",
      "Requirement already satisfied: termcolor~=1.1.0 in c:\\users\\user\\anaconda3\\lib\\site-packages (from tensorflow) (1.1.0)\n",
      "Requirement already satisfied: wrapt~=1.12.1 in c:\\users\\user\\anaconda3\\lib\\site-packages (from tensorflow) (1.12.1)\n",
      "Collecting clang~=5.0\n",
      "  Downloading clang-5.0.tar.gz (30 kB)\n",
      "Collecting tensorboard~=2.6\n",
      "  Downloading tensorboard-2.6.0-py3-none-any.whl (5.6 MB)\n",
      "Requirement already satisfied: protobuf>=3.9.2 in c:\\users\\user\\anaconda3\\lib\\site-packages (from tensorflow) (3.17.3)\n",
      "Requirement already satisfied: absl-py~=0.10 in c:\\users\\user\\anaconda3\\lib\\site-packages (from tensorflow) (0.11.0)\n",
      "Requirement already satisfied: six~=1.15.0 in c:\\users\\user\\anaconda3\\lib\\site-packages (from tensorflow) (1.15.0)\n",
      "Collecting tensorflow-estimator~=2.6\n",
      "  Downloading tensorflow_estimator-2.6.0-py2.py3-none-any.whl (462 kB)\n",
      "Requirement already satisfied: wheel~=0.35 in c:\\users\\user\\anaconda3\\lib\\site-packages (from tensorflow) (0.36.2)\n",
      "Requirement already satisfied: cached-property in c:\\users\\user\\anaconda3\\lib\\site-packages (from h5py~=3.1.0->tensorflow) (1.5.2)\n",
      "Requirement already satisfied: werkzeug>=0.11.15 in c:\\users\\user\\anaconda3\\lib\\site-packages (from tensorboard~=2.6->tensorflow) (0.15.4)\n",
      "Requirement already satisfied: setuptools>=41.0.0 in c:\\users\\user\\anaconda3\\lib\\site-packages (from tensorboard~=2.6->tensorflow) (41.0.1)\n",
      "Requirement already satisfied: markdown>=2.6.8 in c:\\users\\user\\anaconda3\\lib\\site-packages (from tensorboard~=2.6->tensorflow) (3.3.3)\n",
      "Requirement already satisfied: google-auth<2,>=1.6.3 in c:\\users\\user\\anaconda3\\lib\\site-packages (from tensorboard~=2.6->tensorflow) (1.27.0)\n",
      "Requirement already satisfied: requests<3,>=2.21.0 in c:\\users\\user\\anaconda3\\lib\\site-packages (from tensorboard~=2.6->tensorflow) (2.22.0)\n",
      "Requirement already satisfied: tensorboard-data-server<0.7.0,>=0.6.0 in c:\\users\\user\\anaconda3\\lib\\site-packages (from tensorboard~=2.6->tensorflow) (0.6.1)\n",
      "Requirement already satisfied: tensorboard-plugin-wit>=1.6.0 in c:\\users\\user\\anaconda3\\lib\\site-packages (from tensorboard~=2.6->tensorflow) (1.8.0)\n",
      "Requirement already satisfied: google-auth-oauthlib<0.5,>=0.4.1 in c:\\users\\user\\anaconda3\\lib\\site-packages (from tensorboard~=2.6->tensorflow) (0.4.2)\n",
      "Requirement already satisfied: rsa<5,>=3.1.4 in c:\\users\\user\\anaconda3\\lib\\site-packages (from google-auth<2,>=1.6.3->tensorboard~=2.6->tensorflow) (4.7.2)\n",
      "Requirement already satisfied: pyasn1-modules>=0.2.1 in c:\\users\\user\\anaconda3\\lib\\site-packages (from google-auth<2,>=1.6.3->tensorboard~=2.6->tensorflow) (0.2.8)\n",
      "Requirement already satisfied: cachetools<5.0,>=2.0.0 in c:\\users\\user\\anaconda3\\lib\\site-packages (from google-auth<2,>=1.6.3->tensorboard~=2.6->tensorflow) (4.2.1)\n",
      "Requirement already satisfied: requests-oauthlib>=0.7.0 in c:\\users\\user\\anaconda3\\lib\\site-packages (from google-auth-oauthlib<0.5,>=0.4.1->tensorboard~=2.6->tensorflow) (1.3.0)\n",
      "Requirement already satisfied: importlib-metadata in c:\\users\\user\\anaconda3\\lib\\site-packages (from markdown>=2.6.8->tensorboard~=2.6->tensorflow) (2.0.0)\n",
      "Requirement already satisfied: pyasn1<0.5.0,>=0.4.6 in c:\\users\\user\\anaconda3\\lib\\site-packages (from pyasn1-modules>=0.2.1->google-auth<2,>=1.6.3->tensorboard~=2.6->tensorflow) (0.4.8)\n",
      "Requirement already satisfied: idna<2.9,>=2.5 in c:\\users\\user\\anaconda3\\lib\\site-packages (from requests<3,>=2.21.0->tensorboard~=2.6->tensorflow) (2.8)\n",
      "Requirement already satisfied: chardet<3.1.0,>=3.0.2 in c:\\users\\user\\anaconda3\\lib\\site-packages (from requests<3,>=2.21.0->tensorboard~=2.6->tensorflow) (3.0.4)\n",
      "Requirement already satisfied: certifi>=2017.4.17 in c:\\users\\user\\anaconda3\\lib\\site-packages (from requests<3,>=2.21.0->tensorboard~=2.6->tensorflow) (2021.5.30)\n",
      "Requirement already satisfied: urllib3!=1.25.0,!=1.25.1,<1.26,>=1.21.1 in c:\\users\\user\\anaconda3\\lib\\site-packages (from requests<3,>=2.21.0->tensorboard~=2.6->tensorflow) (1.24.2)\n",
      "Requirement already satisfied: oauthlib>=3.0.0 in c:\\users\\user\\anaconda3\\lib\\site-packages (from requests-oauthlib>=0.7.0->google-auth-oauthlib<0.5,>=0.4.1->tensorboard~=2.6->tensorflow) (3.1.0)\n",
      "Requirement already satisfied: zipp>=0.5 in c:\\users\\user\\anaconda3\\lib\\site-packages (from importlib-metadata->markdown>=2.6.8->tensorboard~=2.6->tensorflow) (0.5.1)\n",
      "Building wheels for collected packages: clang\n",
      "  Building wheel for clang (setup.py): started\n",
      "  Building wheel for clang (setup.py): finished with status 'done'\n",
      "  Created wheel for clang: filename=clang-5.0-py3-none-any.whl size=30702 sha256=b4187c744a15c39d620f21de8d4575a44ac5a0b79cdf9abe999ab829bc2a3d2c\n",
      "  Stored in directory: c:\\users\\user\\appdata\\local\\pip\\cache\\wheels\\98\\91\\04\\971b4c587cf47ae952b108949b46926f426c02832d120a082a\n",
      "Successfully built clang\n",
      "Installing collected packages: grpcio, tensorflow-estimator, tensorboard, keras, gast, clang, tensorflow\n",
      "Successfully installed clang-5.0 gast-0.4.0 grpcio-1.40.0 keras-2.6.0 tensorboard-2.6.0 tensorflow-2.6.0 tensorflow-estimator-2.6.0\n"
     ]
    },
    {
     "name": "stderr",
     "output_type": "stream",
     "text": [
      "WARNING: Ignoring invalid distribution -orch (c:\\users\\user\\anaconda3\\lib\\site-packages)\n",
      "WARNING: Ignoring invalid distribution -orch (c:\\users\\user\\anaconda3\\lib\\site-packages)\n",
      "  WARNING: Retrying (Retry(total=4, connect=None, read=None, redirect=None, status=None)) after connection broken by 'NewConnectionError('<pip._vendor.urllib3.connection.HTTPSConnection object at 0x000001AC689686A0>: Failed to establish a new connection: [WinError 10014] 호출에 대한 포인터 인수를 사용하려는 동안 시스템에서 잘못된 포인터 주소를 감지했습니다')': /packages/46/18/cdee520cbd3761e202163f035b647ab1e12b57fd9b7b8c594673a01e4448/tensorflow-2.6.0-cp37-cp37m-win_amd64.whl\n",
      "WARNING: Ignoring invalid distribution -orch (c:\\users\\user\\anaconda3\\lib\\site-packages)\n",
      "  WARNING: The script tensorboard.exe is installed in 'C:\\Users\\USER\\AppData\\Roaming\\Python\\Python37\\Scripts' which is not on PATH.\n",
      "  Consider adding this directory to PATH or, if you prefer to suppress this warning, use --no-warn-script-location.\n",
      "  WARNING: The scripts estimator_ckpt_converter.exe, import_pb_to_tensorboard.exe, saved_model_cli.exe, tensorboard.exe, tf_upgrade_v2.exe, tflite_convert.exe, toco.exe and toco_from_protos.exe are installed in 'C:\\Users\\USER\\AppData\\Roaming\\Python\\Python37\\Scripts' which is not on PATH.\n",
      "  Consider adding this directory to PATH or, if you prefer to suppress this warning, use --no-warn-script-location.\n",
      "ERROR: pip's dependency resolver does not currently take into account all the packages that are installed. This behaviour is the source of the following dependency conflicts.\n",
      "tensorflow-gpu 1.14.0 requires tensorboard<1.15.0,>=1.14.0, but you have tensorboard 2.6.0 which is incompatible.\n",
      "tensorflow-gpu 1.14.0 requires tensorflow-estimator<1.15.0rc0,>=1.14.0rc0, but you have tensorflow-estimator 2.6.0 which is incompatible.\n",
      "WARNING: Ignoring invalid distribution -orch (c:\\users\\user\\anaconda3\\lib\\site-packages)\n",
      "WARNING: Ignoring invalid distribution -orch (c:\\users\\user\\anaconda3\\lib\\site-packages)\n"
     ]
    }
   ],
   "source": [
    "!pip install tensorflow --user --upgrade"
   ]
  },
  {
   "cell_type": "code",
   "execution_count": 2,
   "metadata": {},
   "outputs": [
    {
     "name": "stderr",
     "output_type": "stream",
     "text": [
      "ERROR:root:Internal Python error in the inspect module.\n",
      "Below is the traceback from this internal error.\n",
      "\n"
     ]
    },
    {
     "name": "stdout",
     "output_type": "stream",
     "text": [
      "Traceback (most recent call last):\n",
      "  File \"C:\\Users\\USER\\Anaconda3\\lib\\site-packages\\IPython\\core\\interactiveshell.py\", line 3325, in run_code\n",
      "    exec(code_obj, self.user_global_ns, self.user_ns)\n",
      "  File \"<ipython-input-2-bc4062ad280e>\", line 4, in <module>\n",
      "    from lucid.modelzoo import vision_models\n",
      "ModuleNotFoundError: No module named 'lucid'\n",
      "\n",
      "During handling of the above exception, another exception occurred:\n",
      "\n",
      "Traceback (most recent call last):\n",
      "  File \"C:\\Users\\USER\\Anaconda3\\lib\\site-packages\\IPython\\core\\interactiveshell.py\", line 2039, in showtraceback\n",
      "    stb = value._render_traceback_()\n",
      "AttributeError: 'ModuleNotFoundError' object has no attribute '_render_traceback_'\n",
      "\n",
      "During handling of the above exception, another exception occurred:\n",
      "\n",
      "Traceback (most recent call last):\n",
      "  File \"C:\\Users\\USER\\Anaconda3\\lib\\site-packages\\IPython\\core\\ultratb.py\", line 1101, in get_records\n",
      "    return _fixed_getinnerframes(etb, number_of_lines_of_context, tb_offset)\n",
      "  File \"C:\\Users\\USER\\Anaconda3\\lib\\site-packages\\IPython\\core\\ultratb.py\", line 319, in wrapped\n",
      "    return f(*args, **kwargs)\n",
      "  File \"C:\\Users\\USER\\Anaconda3\\lib\\site-packages\\IPython\\core\\ultratb.py\", line 353, in _fixed_getinnerframes\n",
      "    records = fix_frame_records_filenames(inspect.getinnerframes(etb, context))\n",
      "  File \"C:\\Users\\USER\\Anaconda3\\lib\\inspect.py\", line 1502, in getinnerframes\n",
      "    frameinfo = (tb.tb_frame,) + getframeinfo(tb, context)\n",
      "  File \"C:\\Users\\USER\\Anaconda3\\lib\\inspect.py\", line 1460, in getframeinfo\n",
      "    filename = getsourcefile(frame) or getfile(frame)\n",
      "  File \"C:\\Users\\USER\\Anaconda3\\lib\\inspect.py\", line 696, in getsourcefile\n",
      "    if getattr(getmodule(object, filename), '__loader__', None) is not None:\n",
      "  File \"C:\\Users\\USER\\Anaconda3\\lib\\inspect.py\", line 733, in getmodule\n",
      "    if ismodule(module) and hasattr(module, '__file__'):\n",
      "  File \"C:\\Users\\USER\\Anaconda3\\lib\\site-packages\\tensorflow\\__init__.py\", line 50, in __getattr__\n",
      "    module = self._load()\n",
      "  File \"C:\\Users\\USER\\Anaconda3\\lib\\site-packages\\tensorflow\\__init__.py\", line 44, in _load\n",
      "    module = _importlib.import_module(self.__name__)\n",
      "  File \"C:\\Users\\USER\\Anaconda3\\lib\\importlib\\__init__.py\", line 127, in import_module\n",
      "    return _bootstrap._gcd_import(name[level:], package, level)\n",
      "  File \"<frozen importlib._bootstrap>\", line 1006, in _gcd_import\n",
      "  File \"<frozen importlib._bootstrap>\", line 983, in _find_and_load\n",
      "  File \"<frozen importlib._bootstrap>\", line 965, in _find_and_load_unlocked\n",
      "ModuleNotFoundError: No module named 'tensorflow_core.estimator'\n"
     ]
    },
    {
     "ename": "ModuleNotFoundError",
     "evalue": "No module named 'lucid'",
     "output_type": "error",
     "traceback": [
      "\u001b[1;31m---------------------------------------------------------------------------\u001b[0m"
     ]
    }
   ],
   "source": [
    "import numpy as np\n",
    "import tensorflow as tf\n",
    "\n",
    "from lucid.modelzoo import vision_models\n",
    "from lucid.misc.io import show, load, save\n",
    "from lucid.misc.tfutil import create_session\n",
    "\n",
    "import lucid.optvis.objectives as objectives\n",
    "import lucid.optvis.param as param\n",
    "import lucid.optvis.render as render"
   ]
  },
  {
   "cell_type": "code",
   "execution_count": 3,
   "metadata": {},
   "outputs": [
    {
     "name": "stderr",
     "output_type": "stream",
     "text": [
      "ERROR:root:Internal Python error in the inspect module.\n",
      "Below is the traceback from this internal error.\n",
      "\n"
     ]
    },
    {
     "name": "stdout",
     "output_type": "stream",
     "text": [
      "Traceback (most recent call last):\n",
      "  File \"C:\\Users\\USER\\Anaconda3\\lib\\site-packages\\IPython\\core\\interactiveshell.py\", line 3325, in run_code\n",
      "    exec(code_obj, self.user_global_ns, self.user_ns)\n",
      "  File \"<ipython-input-3-b0d5ecd6eb06>\", line 1, in <module>\n",
      "    from lucid.optvis.objectives import wrap_objective\n",
      "ModuleNotFoundError: No module named 'lucid'\n",
      "\n",
      "During handling of the above exception, another exception occurred:\n",
      "\n",
      "Traceback (most recent call last):\n",
      "  File \"C:\\Users\\USER\\Anaconda3\\lib\\site-packages\\IPython\\core\\interactiveshell.py\", line 2039, in showtraceback\n",
      "    stb = value._render_traceback_()\n",
      "AttributeError: 'ModuleNotFoundError' object has no attribute '_render_traceback_'\n",
      "\n",
      "During handling of the above exception, another exception occurred:\n",
      "\n",
      "Traceback (most recent call last):\n",
      "  File \"C:\\Users\\USER\\Anaconda3\\lib\\site-packages\\IPython\\core\\ultratb.py\", line 1101, in get_records\n",
      "    return _fixed_getinnerframes(etb, number_of_lines_of_context, tb_offset)\n",
      "  File \"C:\\Users\\USER\\Anaconda3\\lib\\site-packages\\IPython\\core\\ultratb.py\", line 319, in wrapped\n",
      "    return f(*args, **kwargs)\n",
      "  File \"C:\\Users\\USER\\Anaconda3\\lib\\site-packages\\IPython\\core\\ultratb.py\", line 353, in _fixed_getinnerframes\n",
      "    records = fix_frame_records_filenames(inspect.getinnerframes(etb, context))\n",
      "  File \"C:\\Users\\USER\\Anaconda3\\lib\\inspect.py\", line 1502, in getinnerframes\n",
      "    frameinfo = (tb.tb_frame,) + getframeinfo(tb, context)\n",
      "  File \"C:\\Users\\USER\\Anaconda3\\lib\\inspect.py\", line 1460, in getframeinfo\n",
      "    filename = getsourcefile(frame) or getfile(frame)\n",
      "  File \"C:\\Users\\USER\\Anaconda3\\lib\\inspect.py\", line 696, in getsourcefile\n",
      "    if getattr(getmodule(object, filename), '__loader__', None) is not None:\n",
      "  File \"C:\\Users\\USER\\Anaconda3\\lib\\inspect.py\", line 733, in getmodule\n",
      "    if ismodule(module) and hasattr(module, '__file__'):\n",
      "  File \"C:\\Users\\USER\\Anaconda3\\lib\\site-packages\\tensorflow\\__init__.py\", line 50, in __getattr__\n",
      "    module = self._load()\n",
      "  File \"C:\\Users\\USER\\Anaconda3\\lib\\site-packages\\tensorflow\\__init__.py\", line 44, in _load\n",
      "    module = _importlib.import_module(self.__name__)\n",
      "  File \"C:\\Users\\USER\\Anaconda3\\lib\\importlib\\__init__.py\", line 127, in import_module\n",
      "    return _bootstrap._gcd_import(name[level:], package, level)\n",
      "  File \"<frozen importlib._bootstrap>\", line 1006, in _gcd_import\n",
      "  File \"<frozen importlib._bootstrap>\", line 983, in _find_and_load\n",
      "  File \"<frozen importlib._bootstrap>\", line 965, in _find_and_load_unlocked\n",
      "ModuleNotFoundError: No module named 'tensorflow_core.estimator'\n"
     ]
    },
    {
     "ename": "ModuleNotFoundError",
     "evalue": "No module named 'lucid'",
     "output_type": "error",
     "traceback": [
      "\u001b[1;31m---------------------------------------------------------------------------\u001b[0m"
     ]
    }
   ],
   "source": [
    "from lucid.optvis.objectives import wrap_objective"
   ]
  },
  {
   "cell_type": "code",
   "execution_count": 4,
   "metadata": {},
   "outputs": [
    {
     "name": "stderr",
     "output_type": "stream",
     "text": [
      "ERROR:root:Internal Python error in the inspect module.\n",
      "Below is the traceback from this internal error.\n",
      "\n"
     ]
    },
    {
     "name": "stdout",
     "output_type": "stream",
     "text": [
      "Traceback (most recent call last):\n",
      "  File \"C:\\Users\\USER\\Anaconda3\\lib\\site-packages\\IPython\\core\\interactiveshell.py\", line 3325, in run_code\n",
      "    exec(code_obj, self.user_global_ns, self.user_ns)\n",
      "  File \"<ipython-input-4-2b4f15d5d308>\", line 1, in <module>\n",
      "    model = vision_models.InceptionV1()\n",
      "NameError: name 'vision_models' is not defined\n",
      "\n",
      "During handling of the above exception, another exception occurred:\n",
      "\n",
      "Traceback (most recent call last):\n",
      "  File \"C:\\Users\\USER\\Anaconda3\\lib\\site-packages\\IPython\\core\\interactiveshell.py\", line 2039, in showtraceback\n",
      "    stb = value._render_traceback_()\n",
      "AttributeError: 'NameError' object has no attribute '_render_traceback_'\n",
      "\n",
      "During handling of the above exception, another exception occurred:\n",
      "\n",
      "Traceback (most recent call last):\n",
      "  File \"C:\\Users\\USER\\Anaconda3\\lib\\site-packages\\IPython\\core\\ultratb.py\", line 1101, in get_records\n",
      "    return _fixed_getinnerframes(etb, number_of_lines_of_context, tb_offset)\n",
      "  File \"C:\\Users\\USER\\Anaconda3\\lib\\site-packages\\IPython\\core\\ultratb.py\", line 319, in wrapped\n",
      "    return f(*args, **kwargs)\n",
      "  File \"C:\\Users\\USER\\Anaconda3\\lib\\site-packages\\IPython\\core\\ultratb.py\", line 353, in _fixed_getinnerframes\n",
      "    records = fix_frame_records_filenames(inspect.getinnerframes(etb, context))\n",
      "  File \"C:\\Users\\USER\\Anaconda3\\lib\\inspect.py\", line 1502, in getinnerframes\n",
      "    frameinfo = (tb.tb_frame,) + getframeinfo(tb, context)\n",
      "  File \"C:\\Users\\USER\\Anaconda3\\lib\\inspect.py\", line 1460, in getframeinfo\n",
      "    filename = getsourcefile(frame) or getfile(frame)\n",
      "  File \"C:\\Users\\USER\\Anaconda3\\lib\\inspect.py\", line 696, in getsourcefile\n",
      "    if getattr(getmodule(object, filename), '__loader__', None) is not None:\n",
      "  File \"C:\\Users\\USER\\Anaconda3\\lib\\inspect.py\", line 733, in getmodule\n",
      "    if ismodule(module) and hasattr(module, '__file__'):\n",
      "  File \"C:\\Users\\USER\\Anaconda3\\lib\\site-packages\\tensorflow\\__init__.py\", line 50, in __getattr__\n",
      "    module = self._load()\n",
      "  File \"C:\\Users\\USER\\Anaconda3\\lib\\site-packages\\tensorflow\\__init__.py\", line 44, in _load\n",
      "    module = _importlib.import_module(self.__name__)\n",
      "  File \"C:\\Users\\USER\\Anaconda3\\lib\\importlib\\__init__.py\", line 127, in import_module\n",
      "    return _bootstrap._gcd_import(name[level:], package, level)\n",
      "  File \"<frozen importlib._bootstrap>\", line 1006, in _gcd_import\n",
      "  File \"<frozen importlib._bootstrap>\", line 983, in _find_and_load\n",
      "  File \"<frozen importlib._bootstrap>\", line 965, in _find_and_load_unlocked\n",
      "ModuleNotFoundError: No module named 'tensorflow_core.estimator'\n"
     ]
    },
    {
     "ename": "NameError",
     "evalue": "name 'vision_models' is not defined",
     "output_type": "error",
     "traceback": [
      "\u001b[1;31m---------------------------------------------------------------------------\u001b[0m"
     ]
    }
   ],
   "source": [
    "model = vision_models.InceptionV1()\n",
    "model.load_graphdef()"
   ]
  },
  {
   "cell_type": "code",
   "execution_count": 5,
   "metadata": {},
   "outputs": [
    {
     "data": {
      "text/plain": [
       "False"
      ]
     },
     "execution_count": 5,
     "metadata": {},
     "output_type": "execute_result"
    }
   ],
   "source": [
    "tf.test.is_gpu_available()"
   ]
  },
  {
   "cell_type": "code",
   "execution_count": 7,
   "metadata": {},
   "outputs": [
    {
     "name": "stderr",
     "output_type": "stream",
     "text": [
      "ERROR:root:Internal Python error in the inspect module.\n",
      "Below is the traceback from this internal error.\n",
      "\n"
     ]
    },
    {
     "name": "stdout",
     "output_type": "stream",
     "text": [
      "Traceback (most recent call last):\n",
      "  File \"C:\\Users\\USER\\Anaconda3\\lib\\site-packages\\IPython\\core\\interactiveshell.py\", line 3325, in run_code\n",
      "    exec(code_obj, self.user_global_ns, self.user_ns)\n",
      "  File \"<ipython-input-7-8c4a2d2ac94f>\", line 1, in <module>\n",
      "    content_image = load(\"https://storage.googleapis.com/tensorflow-lucid/static/img/notebook-styletransfer-bigben.jpg\")\n",
      "NameError: name 'load' is not defined\n",
      "\n",
      "During handling of the above exception, another exception occurred:\n",
      "\n",
      "Traceback (most recent call last):\n",
      "  File \"C:\\Users\\USER\\Anaconda3\\lib\\site-packages\\IPython\\core\\interactiveshell.py\", line 2039, in showtraceback\n",
      "    stb = value._render_traceback_()\n",
      "AttributeError: 'NameError' object has no attribute '_render_traceback_'\n",
      "\n",
      "During handling of the above exception, another exception occurred:\n",
      "\n",
      "Traceback (most recent call last):\n",
      "  File \"C:\\Users\\USER\\Anaconda3\\lib\\site-packages\\IPython\\core\\ultratb.py\", line 1101, in get_records\n",
      "    return _fixed_getinnerframes(etb, number_of_lines_of_context, tb_offset)\n",
      "  File \"C:\\Users\\USER\\Anaconda3\\lib\\site-packages\\IPython\\core\\ultratb.py\", line 319, in wrapped\n",
      "    return f(*args, **kwargs)\n",
      "  File \"C:\\Users\\USER\\Anaconda3\\lib\\site-packages\\IPython\\core\\ultratb.py\", line 353, in _fixed_getinnerframes\n",
      "    records = fix_frame_records_filenames(inspect.getinnerframes(etb, context))\n",
      "  File \"C:\\Users\\USER\\Anaconda3\\lib\\inspect.py\", line 1502, in getinnerframes\n",
      "    frameinfo = (tb.tb_frame,) + getframeinfo(tb, context)\n",
      "  File \"C:\\Users\\USER\\Anaconda3\\lib\\inspect.py\", line 1460, in getframeinfo\n",
      "    filename = getsourcefile(frame) or getfile(frame)\n",
      "  File \"C:\\Users\\USER\\Anaconda3\\lib\\inspect.py\", line 696, in getsourcefile\n",
      "    if getattr(getmodule(object, filename), '__loader__', None) is not None:\n",
      "  File \"C:\\Users\\USER\\Anaconda3\\lib\\inspect.py\", line 733, in getmodule\n",
      "    if ismodule(module) and hasattr(module, '__file__'):\n",
      "  File \"C:\\Users\\USER\\Anaconda3\\lib\\site-packages\\tensorflow\\__init__.py\", line 50, in __getattr__\n",
      "    module = self._load()\n",
      "  File \"C:\\Users\\USER\\Anaconda3\\lib\\site-packages\\tensorflow\\__init__.py\", line 44, in _load\n",
      "    module = _importlib.import_module(self.__name__)\n",
      "  File \"C:\\Users\\USER\\Anaconda3\\lib\\importlib\\__init__.py\", line 127, in import_module\n",
      "    return _bootstrap._gcd_import(name[level:], package, level)\n",
      "  File \"<frozen importlib._bootstrap>\", line 1006, in _gcd_import\n",
      "  File \"<frozen importlib._bootstrap>\", line 983, in _find_and_load\n",
      "  File \"<frozen importlib._bootstrap>\", line 965, in _find_and_load_unlocked\n",
      "ModuleNotFoundError: No module named 'tensorflow_core.estimator'\n"
     ]
    },
    {
     "ename": "NameError",
     "evalue": "name 'load' is not defined",
     "output_type": "error",
     "traceback": [
      "\u001b[1;31m---------------------------------------------------------------------------\u001b[0m"
     ]
    }
   ],
   "source": [
    "content_image = load(\"https://storage.googleapis.com/tensorflow-lucid/static/img/notebook-styletransfer-bigben.jpg\")\n",
    "style_image = load(\"https://storage.googleapis.com/tensorflow-lucid/static/img/starry-night.png\")[..., :3] # removes transparency channel\n",
    "\n",
    "print(content_image.shape, style_image.shape)\n",
    "\n",
    "show(content_image)\n",
    "show(style_image)"
   ]
  },
  {
   "cell_type": "code",
   "execution_count": 8,
   "metadata": {},
   "outputs": [],
   "source": [
    "style_layers = [\n",
    "  'conv2d2',\n",
    "  'mixed3a',\n",
    "  'mixed4a',\n",
    "  'mixed4b',\n",
    "  'mixed4c',\n",
    "]\n",
    "\n",
    "content_layers = [\n",
    "  'mixed3b',\n",
    "]"
   ]
  },
  {
   "cell_type": "code",
   "execution_count": 10,
   "metadata": {},
   "outputs": [],
   "source": [
    "def style_transfer_param(content_image, style_image, decorrelate=True, fft=True):\n",
    "    style_transfer_input = param.image(*content_image.shape[:2], decorrelate=decorrelate, fft=fft)[0]\n",
    "    content_input = content_image\n",
    "    style_input = tf.random_crop(style_image, content_image.shape)\n",
    "    return tf.stack([style_transfer_input, content_input, style_input])\n",
    "\n",
    "# these constants help remember which image is at which batch dimension\n",
    "TRANSFER_INDEX = 0\n",
    "CONTENT_INDEX = 1\n",
    "STYLE_INDEX = 2"
   ]
  },
  {
   "cell_type": "code",
   "execution_count": 11,
   "metadata": {},
   "outputs": [
    {
     "name": "stderr",
     "output_type": "stream",
     "text": [
      "ERROR:root:Internal Python error in the inspect module.\n",
      "Below is the traceback from this internal error.\n",
      "\n"
     ]
    },
    {
     "name": "stdout",
     "output_type": "stream",
     "text": [
      "Traceback (most recent call last):\n",
      "  File \"C:\\Users\\USER\\Anaconda3\\lib\\site-packages\\IPython\\core\\interactiveshell.py\", line 3325, in run_code\n",
      "    exec(code_obj, self.user_global_ns, self.user_ns)\n",
      "  File \"<ipython-input-11-0bf38a450f4d>\", line 1, in <module>\n",
      "    style_transfer_param(content_image, style_image).shape\n",
      "NameError: name 'content_image' is not defined\n",
      "\n",
      "During handling of the above exception, another exception occurred:\n",
      "\n",
      "Traceback (most recent call last):\n",
      "  File \"C:\\Users\\USER\\Anaconda3\\lib\\site-packages\\IPython\\core\\interactiveshell.py\", line 2039, in showtraceback\n",
      "    stb = value._render_traceback_()\n",
      "AttributeError: 'NameError' object has no attribute '_render_traceback_'\n",
      "\n",
      "During handling of the above exception, another exception occurred:\n",
      "\n",
      "Traceback (most recent call last):\n",
      "  File \"C:\\Users\\USER\\Anaconda3\\lib\\site-packages\\IPython\\core\\ultratb.py\", line 1101, in get_records\n",
      "    return _fixed_getinnerframes(etb, number_of_lines_of_context, tb_offset)\n",
      "  File \"C:\\Users\\USER\\Anaconda3\\lib\\site-packages\\IPython\\core\\ultratb.py\", line 319, in wrapped\n",
      "    return f(*args, **kwargs)\n",
      "  File \"C:\\Users\\USER\\Anaconda3\\lib\\site-packages\\IPython\\core\\ultratb.py\", line 353, in _fixed_getinnerframes\n",
      "    records = fix_frame_records_filenames(inspect.getinnerframes(etb, context))\n",
      "  File \"C:\\Users\\USER\\Anaconda3\\lib\\inspect.py\", line 1502, in getinnerframes\n",
      "    frameinfo = (tb.tb_frame,) + getframeinfo(tb, context)\n",
      "  File \"C:\\Users\\USER\\Anaconda3\\lib\\inspect.py\", line 1460, in getframeinfo\n",
      "    filename = getsourcefile(frame) or getfile(frame)\n",
      "  File \"C:\\Users\\USER\\Anaconda3\\lib\\inspect.py\", line 696, in getsourcefile\n",
      "    if getattr(getmodule(object, filename), '__loader__', None) is not None:\n",
      "  File \"C:\\Users\\USER\\Anaconda3\\lib\\inspect.py\", line 733, in getmodule\n",
      "    if ismodule(module) and hasattr(module, '__file__'):\n",
      "  File \"C:\\Users\\USER\\Anaconda3\\lib\\site-packages\\tensorflow\\__init__.py\", line 50, in __getattr__\n",
      "    module = self._load()\n",
      "  File \"C:\\Users\\USER\\Anaconda3\\lib\\site-packages\\tensorflow\\__init__.py\", line 44, in _load\n",
      "    module = _importlib.import_module(self.__name__)\n",
      "  File \"C:\\Users\\USER\\Anaconda3\\lib\\importlib\\__init__.py\", line 127, in import_module\n",
      "    return _bootstrap._gcd_import(name[level:], package, level)\n",
      "  File \"<frozen importlib._bootstrap>\", line 1006, in _gcd_import\n",
      "  File \"<frozen importlib._bootstrap>\", line 983, in _find_and_load\n",
      "  File \"<frozen importlib._bootstrap>\", line 965, in _find_and_load_unlocked\n",
      "ModuleNotFoundError: No module named 'tensorflow_core.estimator'\n"
     ]
    },
    {
     "ename": "NameError",
     "evalue": "name 'content_image' is not defined",
     "output_type": "error",
     "traceback": [
      "\u001b[1;31m---------------------------------------------------------------------------\u001b[0m"
     ]
    }
   ],
   "source": [
    "style_transfer_param(content_image, style_image).shape"
   ]
  },
  {
   "cell_type": "code",
   "execution_count": 13,
   "metadata": {},
   "outputs": [],
   "source": [
    "def mean_L1(a, b):\n",
    "    return tf.reduce_mean(tf.abs(a-b))"
   ]
  },
  {
   "cell_type": "code",
   "execution_count": 18,
   "metadata": {},
   "outputs": [
    {
     "name": "stderr",
     "output_type": "stream",
     "text": [
      "ERROR:root:Internal Python error in the inspect module.\n",
      "Below is the traceback from this internal error.\n",
      "\n"
     ]
    },
    {
     "name": "stdout",
     "output_type": "stream",
     "text": [
      "Traceback (most recent call last):\n",
      "  File \"C:\\Users\\USER\\Anaconda3\\lib\\site-packages\\IPython\\core\\interactiveshell.py\", line 3325, in run_code\n",
      "    exec(code_obj, self.user_global_ns, self.user_ns)\n",
      "  File \"<ipython-input-18-57cfb3e1f0af>\", line 1, in <module>\n",
      "    @wrap_objective\n",
      "NameError: name 'wrap_objective' is not defined\n",
      "\n",
      "During handling of the above exception, another exception occurred:\n",
      "\n",
      "Traceback (most recent call last):\n",
      "  File \"C:\\Users\\USER\\Anaconda3\\lib\\site-packages\\IPython\\core\\interactiveshell.py\", line 2039, in showtraceback\n",
      "    stb = value._render_traceback_()\n",
      "AttributeError: 'NameError' object has no attribute '_render_traceback_'\n",
      "\n",
      "During handling of the above exception, another exception occurred:\n",
      "\n",
      "Traceback (most recent call last):\n",
      "  File \"C:\\Users\\USER\\Anaconda3\\lib\\site-packages\\IPython\\core\\ultratb.py\", line 1101, in get_records\n",
      "    return _fixed_getinnerframes(etb, number_of_lines_of_context, tb_offset)\n",
      "  File \"C:\\Users\\USER\\Anaconda3\\lib\\site-packages\\IPython\\core\\ultratb.py\", line 319, in wrapped\n",
      "    return f(*args, **kwargs)\n",
      "  File \"C:\\Users\\USER\\Anaconda3\\lib\\site-packages\\IPython\\core\\ultratb.py\", line 353, in _fixed_getinnerframes\n",
      "    records = fix_frame_records_filenames(inspect.getinnerframes(etb, context))\n",
      "  File \"C:\\Users\\USER\\Anaconda3\\lib\\inspect.py\", line 1502, in getinnerframes\n",
      "    frameinfo = (tb.tb_frame,) + getframeinfo(tb, context)\n",
      "  File \"C:\\Users\\USER\\Anaconda3\\lib\\inspect.py\", line 1460, in getframeinfo\n",
      "    filename = getsourcefile(frame) or getfile(frame)\n",
      "  File \"C:\\Users\\USER\\Anaconda3\\lib\\inspect.py\", line 696, in getsourcefile\n",
      "    if getattr(getmodule(object, filename), '__loader__', None) is not None:\n",
      "  File \"C:\\Users\\USER\\Anaconda3\\lib\\inspect.py\", line 733, in getmodule\n",
      "    if ismodule(module) and hasattr(module, '__file__'):\n",
      "  File \"C:\\Users\\USER\\Anaconda3\\lib\\site-packages\\tensorflow\\__init__.py\", line 50, in __getattr__\n",
      "    module = self._load()\n",
      "  File \"C:\\Users\\USER\\Anaconda3\\lib\\site-packages\\tensorflow\\__init__.py\", line 44, in _load\n",
      "    module = _importlib.import_module(self.__name__)\n",
      "  File \"C:\\Users\\USER\\Anaconda3\\lib\\importlib\\__init__.py\", line 127, in import_module\n",
      "    return _bootstrap._gcd_import(name[level:], package, level)\n",
      "  File \"<frozen importlib._bootstrap>\", line 1006, in _gcd_import\n",
      "  File \"<frozen importlib._bootstrap>\", line 983, in _find_and_load\n",
      "  File \"<frozen importlib._bootstrap>\", line 965, in _find_and_load_unlocked\n",
      "ModuleNotFoundError: No module named 'tensorflow_core.estimator'\n"
     ]
    },
    {
     "ename": "NameError",
     "evalue": "name 'wrap_objective' is not defined",
     "output_type": "error",
     "traceback": [
      "\u001b[1;31m---------------------------------------------------------------------------\u001b[0m"
     ]
    }
   ],
   "source": [
    "@wrap_objective\n",
    "def activation_difference(layer_names, activation_loss_f=mean_L1, transform_f=None, difference_to=CONTENT_INDEX):\n",
    "  def inner(T):\n",
    "    # first we collect the (constant) activations of image we're computing the difference to\n",
    "    image_activations = [T(layer_name)[difference_to] for layer_name in layer_names]\n",
    "    if transform_f is not None:\n",
    "      image_activations = [transform_f(act) for act in image_activations]\n",
    "\n",
    "    # we also set get the activations of the optimized image which will change during optimization\n",
    "    optimization_activations = [T(layer)[TRANSFER_INDEX] for layer in layer_names]\n",
    "    if transform_f is not None:\n",
    "      optimization_activations = [transform_f(act) for act in optimization_activations]\n",
    "\n",
    "    # we use the supplied loss function to compute the actual losses\n",
    "    losses = [activation_loss_f(a, b) for a, b in zip(image_activations, optimization_activations)]\n",
    "    return tf.add_n(losses)\n",
    "\n",
    "  return inner"
   ]
  },
  {
   "cell_type": "code",
   "execution_count": 19,
   "metadata": {},
   "outputs": [],
   "source": [
    "def gram_matrix(array, normalize_magnitue=True):\n",
    "  channels = tf.shape(array)[-1]\n",
    "  array_flat = tf.reshape(array, [-1, channels])\n",
    "  gram_matrix = tf.matmul(array_flat, array_flat, transpose_a=True)\n",
    "  if normalize_magnitue:\n",
    "    length = tf.shape(array_flat)[0]\n",
    "    gram_matrix /= tf.cast(length, tf.float32)\n",
    "  return gram_matrix"
   ]
  },
  {
   "cell_type": "code",
   "execution_count": 20,
   "metadata": {},
   "outputs": [
    {
     "name": "stderr",
     "output_type": "stream",
     "text": [
      "ERROR:root:Internal Python error in the inspect module.\n",
      "Below is the traceback from this internal error.\n",
      "\n"
     ]
    },
    {
     "name": "stdout",
     "output_type": "stream",
     "text": [
      "Traceback (most recent call last):\n",
      "  File \"C:\\Users\\USER\\Anaconda3\\lib\\site-packages\\IPython\\core\\interactiveshell.py\", line 3325, in run_code\n",
      "    exec(code_obj, self.user_global_ns, self.user_ns)\n",
      "  File \"<ipython-input-20-00eaf867df07>\", line 3, in <module>\n",
      "    content_obj = 100 * activation_difference(content_layers, difference_to=CONTENT_INDEX)\n",
      "NameError: name 'activation_difference' is not defined\n",
      "\n",
      "During handling of the above exception, another exception occurred:\n",
      "\n",
      "Traceback (most recent call last):\n",
      "  File \"C:\\Users\\USER\\Anaconda3\\lib\\site-packages\\IPython\\core\\interactiveshell.py\", line 2039, in showtraceback\n",
      "    stb = value._render_traceback_()\n",
      "AttributeError: 'NameError' object has no attribute '_render_traceback_'\n",
      "\n",
      "During handling of the above exception, another exception occurred:\n",
      "\n",
      "Traceback (most recent call last):\n",
      "  File \"C:\\Users\\USER\\Anaconda3\\lib\\site-packages\\IPython\\core\\ultratb.py\", line 1101, in get_records\n",
      "    return _fixed_getinnerframes(etb, number_of_lines_of_context, tb_offset)\n",
      "  File \"C:\\Users\\USER\\Anaconda3\\lib\\site-packages\\IPython\\core\\ultratb.py\", line 319, in wrapped\n",
      "    return f(*args, **kwargs)\n",
      "  File \"C:\\Users\\USER\\Anaconda3\\lib\\site-packages\\IPython\\core\\ultratb.py\", line 353, in _fixed_getinnerframes\n",
      "    records = fix_frame_records_filenames(inspect.getinnerframes(etb, context))\n",
      "  File \"C:\\Users\\USER\\Anaconda3\\lib\\inspect.py\", line 1502, in getinnerframes\n",
      "    frameinfo = (tb.tb_frame,) + getframeinfo(tb, context)\n",
      "  File \"C:\\Users\\USER\\Anaconda3\\lib\\inspect.py\", line 1460, in getframeinfo\n",
      "    filename = getsourcefile(frame) or getfile(frame)\n",
      "  File \"C:\\Users\\USER\\Anaconda3\\lib\\inspect.py\", line 696, in getsourcefile\n",
      "    if getattr(getmodule(object, filename), '__loader__', None) is not None:\n",
      "  File \"C:\\Users\\USER\\Anaconda3\\lib\\inspect.py\", line 733, in getmodule\n",
      "    if ismodule(module) and hasattr(module, '__file__'):\n",
      "  File \"C:\\Users\\USER\\Anaconda3\\lib\\site-packages\\tensorflow\\__init__.py\", line 50, in __getattr__\n",
      "    module = self._load()\n",
      "  File \"C:\\Users\\USER\\Anaconda3\\lib\\site-packages\\tensorflow\\__init__.py\", line 44, in _load\n",
      "    module = _importlib.import_module(self.__name__)\n",
      "  File \"C:\\Users\\USER\\Anaconda3\\lib\\importlib\\__init__.py\", line 127, in import_module\n",
      "    return _bootstrap._gcd_import(name[level:], package, level)\n",
      "  File \"<frozen importlib._bootstrap>\", line 1006, in _gcd_import\n",
      "  File \"<frozen importlib._bootstrap>\", line 983, in _find_and_load\n",
      "  File \"<frozen importlib._bootstrap>\", line 965, in _find_and_load_unlocked\n",
      "ModuleNotFoundError: No module named 'tensorflow_core.estimator'\n"
     ]
    },
    {
     "ename": "NameError",
     "evalue": "name 'activation_difference' is not defined",
     "output_type": "error",
     "traceback": [
      "\u001b[1;31m---------------------------------------------------------------------------\u001b[0m"
     ]
    }
   ],
   "source": [
    "param_f = lambda: style_transfer_param(content_image, style_image)\n",
    "\n",
    "content_obj = 100 * activation_difference(content_layers, difference_to=CONTENT_INDEX)\n",
    "content_obj.description = \"Content Loss\"\n",
    "\n",
    "style_obj = activation_difference(style_layers, transform_f=gram_matrix, difference_to=STYLE_INDEX)\n",
    "style_obj.description = \"Style Loss\"\n",
    "\n",
    "objective = - content_obj - style_obj\n",
    "\n",
    "vis = render.render_vis(model, objective, param_f=param_f, thresholds=[512], verbose=False, print_objectives=[content_obj, style_obj])[-1]"
   ]
  },
  {
   "cell_type": "code",
   "execution_count": 21,
   "metadata": {},
   "outputs": [
    {
     "name": "stderr",
     "output_type": "stream",
     "text": [
      "ERROR:root:Internal Python error in the inspect module.\n",
      "Below is the traceback from this internal error.\n",
      "\n"
     ]
    },
    {
     "name": "stdout",
     "output_type": "stream",
     "text": [
      "Traceback (most recent call last):\n",
      "  File \"C:\\Users\\USER\\Anaconda3\\lib\\site-packages\\IPython\\core\\interactiveshell.py\", line 3325, in run_code\n",
      "    exec(code_obj, self.user_global_ns, self.user_ns)\n",
      "  File \"<ipython-input-21-12ea8564a64f>\", line 1, in <module>\n",
      "    show(vis)\n",
      "NameError: name 'show' is not defined\n",
      "\n",
      "During handling of the above exception, another exception occurred:\n",
      "\n",
      "Traceback (most recent call last):\n",
      "  File \"C:\\Users\\USER\\Anaconda3\\lib\\site-packages\\IPython\\core\\interactiveshell.py\", line 2039, in showtraceback\n",
      "    stb = value._render_traceback_()\n",
      "AttributeError: 'NameError' object has no attribute '_render_traceback_'\n",
      "\n",
      "During handling of the above exception, another exception occurred:\n",
      "\n",
      "Traceback (most recent call last):\n",
      "  File \"C:\\Users\\USER\\Anaconda3\\lib\\site-packages\\IPython\\core\\ultratb.py\", line 1101, in get_records\n",
      "    return _fixed_getinnerframes(etb, number_of_lines_of_context, tb_offset)\n",
      "  File \"C:\\Users\\USER\\Anaconda3\\lib\\site-packages\\IPython\\core\\ultratb.py\", line 319, in wrapped\n",
      "    return f(*args, **kwargs)\n",
      "  File \"C:\\Users\\USER\\Anaconda3\\lib\\site-packages\\IPython\\core\\ultratb.py\", line 353, in _fixed_getinnerframes\n",
      "    records = fix_frame_records_filenames(inspect.getinnerframes(etb, context))\n",
      "  File \"C:\\Users\\USER\\Anaconda3\\lib\\inspect.py\", line 1502, in getinnerframes\n",
      "    frameinfo = (tb.tb_frame,) + getframeinfo(tb, context)\n",
      "  File \"C:\\Users\\USER\\Anaconda3\\lib\\inspect.py\", line 1460, in getframeinfo\n",
      "    filename = getsourcefile(frame) or getfile(frame)\n",
      "  File \"C:\\Users\\USER\\Anaconda3\\lib\\inspect.py\", line 696, in getsourcefile\n",
      "    if getattr(getmodule(object, filename), '__loader__', None) is not None:\n",
      "  File \"C:\\Users\\USER\\Anaconda3\\lib\\inspect.py\", line 733, in getmodule\n",
      "    if ismodule(module) and hasattr(module, '__file__'):\n",
      "  File \"C:\\Users\\USER\\Anaconda3\\lib\\site-packages\\tensorflow\\__init__.py\", line 50, in __getattr__\n",
      "    module = self._load()\n",
      "  File \"C:\\Users\\USER\\Anaconda3\\lib\\site-packages\\tensorflow\\__init__.py\", line 44, in _load\n",
      "    module = _importlib.import_module(self.__name__)\n",
      "  File \"C:\\Users\\USER\\Anaconda3\\lib\\importlib\\__init__.py\", line 127, in import_module\n",
      "    return _bootstrap._gcd_import(name[level:], package, level)\n",
      "  File \"<frozen importlib._bootstrap>\", line 1006, in _gcd_import\n",
      "  File \"<frozen importlib._bootstrap>\", line 983, in _find_and_load\n",
      "  File \"<frozen importlib._bootstrap>\", line 965, in _find_and_load_unlocked\n",
      "ModuleNotFoundError: No module named 'tensorflow_core.estimator'\n"
     ]
    },
    {
     "ename": "NameError",
     "evalue": "name 'show' is not defined",
     "output_type": "error",
     "traceback": [
      "\u001b[1;31m---------------------------------------------------------------------------\u001b[0m"
     ]
    }
   ],
   "source": [
    "show(vis)"
   ]
  },
  {
   "cell_type": "code",
   "execution_count": 22,
   "metadata": {},
   "outputs": [],
   "source": [
    "param_f = lambda: param.image(width, height, decorrelate=True, fft=True)"
   ]
  },
  {
   "cell_type": "code",
   "execution_count": 23,
   "metadata": {},
   "outputs": [
    {
     "name": "stderr",
     "output_type": "stream",
     "text": [
      "ERROR:root:Internal Python error in the inspect module.\n",
      "Below is the traceback from this internal error.\n",
      "\n"
     ]
    },
    {
     "name": "stdout",
     "output_type": "stream",
     "text": [
      "Traceback (most recent call last):\n",
      "  File \"C:\\Users\\USER\\Anaconda3\\lib\\site-packages\\IPython\\core\\interactiveshell.py\", line 3325, in run_code\n",
      "    exec(code_obj, self.user_global_ns, self.user_ns)\n",
      "  File \"<ipython-input-23-63d70b6b809b>\", line 3, in <module>\n",
      "    bad_param_vis = render.render_vis(model, objective, param_f, verbose=True, thresholds=(25, 75, 150, 300, 512), print_objectives=[content_obj, style_obj])[-1]\n",
      "NameError: name 'render' is not defined\n",
      "\n",
      "During handling of the above exception, another exception occurred:\n",
      "\n",
      "Traceback (most recent call last):\n",
      "  File \"C:\\Users\\USER\\Anaconda3\\lib\\site-packages\\IPython\\core\\interactiveshell.py\", line 2039, in showtraceback\n",
      "    stb = value._render_traceback_()\n",
      "AttributeError: 'NameError' object has no attribute '_render_traceback_'\n",
      "\n",
      "During handling of the above exception, another exception occurred:\n",
      "\n",
      "Traceback (most recent call last):\n",
      "  File \"C:\\Users\\USER\\Anaconda3\\lib\\site-packages\\IPython\\core\\ultratb.py\", line 1101, in get_records\n",
      "    return _fixed_getinnerframes(etb, number_of_lines_of_context, tb_offset)\n",
      "  File \"C:\\Users\\USER\\Anaconda3\\lib\\site-packages\\IPython\\core\\ultratb.py\", line 319, in wrapped\n",
      "    return f(*args, **kwargs)\n",
      "  File \"C:\\Users\\USER\\Anaconda3\\lib\\site-packages\\IPython\\core\\ultratb.py\", line 353, in _fixed_getinnerframes\n",
      "    records = fix_frame_records_filenames(inspect.getinnerframes(etb, context))\n",
      "  File \"C:\\Users\\USER\\Anaconda3\\lib\\inspect.py\", line 1502, in getinnerframes\n",
      "    frameinfo = (tb.tb_frame,) + getframeinfo(tb, context)\n",
      "  File \"C:\\Users\\USER\\Anaconda3\\lib\\inspect.py\", line 1460, in getframeinfo\n",
      "    filename = getsourcefile(frame) or getfile(frame)\n",
      "  File \"C:\\Users\\USER\\Anaconda3\\lib\\inspect.py\", line 696, in getsourcefile\n",
      "    if getattr(getmodule(object, filename), '__loader__', None) is not None:\n",
      "  File \"C:\\Users\\USER\\Anaconda3\\lib\\inspect.py\", line 733, in getmodule\n",
      "    if ismodule(module) and hasattr(module, '__file__'):\n",
      "  File \"C:\\Users\\USER\\Anaconda3\\lib\\site-packages\\tensorflow\\__init__.py\", line 50, in __getattr__\n",
      "    module = self._load()\n",
      "  File \"C:\\Users\\USER\\Anaconda3\\lib\\site-packages\\tensorflow\\__init__.py\", line 44, in _load\n",
      "    module = _importlib.import_module(self.__name__)\n",
      "  File \"C:\\Users\\USER\\Anaconda3\\lib\\importlib\\__init__.py\", line 127, in import_module\n",
      "    return _bootstrap._gcd_import(name[level:], package, level)\n",
      "  File \"<frozen importlib._bootstrap>\", line 1006, in _gcd_import\n",
      "  File \"<frozen importlib._bootstrap>\", line 983, in _find_and_load\n",
      "  File \"<frozen importlib._bootstrap>\", line 965, in _find_and_load_unlocked\n",
      "ModuleNotFoundError: No module named 'tensorflow_core.estimator'\n"
     ]
    },
    {
     "ename": "NameError",
     "evalue": "name 'render' is not defined",
     "output_type": "error",
     "traceback": [
      "\u001b[1;31m---------------------------------------------------------------------------\u001b[0m"
     ]
    }
   ],
   "source": [
    "param_f = lambda: style_transfer_param(content_image, style_image, decorrelate=False, fft=False)\n",
    "\n",
    "bad_param_vis = render.render_vis(model, objective, param_f, verbose=True, thresholds=(25, 75, 150, 300, 512), print_objectives=[content_obj, style_obj])[-1]"
   ]
  },
  {
   "cell_type": "code",
   "execution_count": 24,
   "metadata": {},
   "outputs": [
    {
     "name": "stderr",
     "output_type": "stream",
     "text": [
      "ERROR:root:Internal Python error in the inspect module.\n",
      "Below is the traceback from this internal error.\n",
      "\n"
     ]
    },
    {
     "name": "stdout",
     "output_type": "stream",
     "text": [
      "Traceback (most recent call last):\n",
      "  File \"C:\\Users\\USER\\Anaconda3\\lib\\site-packages\\IPython\\core\\interactiveshell.py\", line 3325, in run_code\n",
      "    exec(code_obj, self.user_global_ns, self.user_ns)\n",
      "  File \"<ipython-input-24-75252ad1e00f>\", line 1, in <module>\n",
      "    show(bad_param_vis[0])\n",
      "NameError: name 'show' is not defined\n",
      "\n",
      "During handling of the above exception, another exception occurred:\n",
      "\n",
      "Traceback (most recent call last):\n",
      "  File \"C:\\Users\\USER\\Anaconda3\\lib\\site-packages\\IPython\\core\\interactiveshell.py\", line 2039, in showtraceback\n",
      "    stb = value._render_traceback_()\n",
      "AttributeError: 'NameError' object has no attribute '_render_traceback_'\n",
      "\n",
      "During handling of the above exception, another exception occurred:\n",
      "\n",
      "Traceback (most recent call last):\n",
      "  File \"C:\\Users\\USER\\Anaconda3\\lib\\site-packages\\IPython\\core\\ultratb.py\", line 1101, in get_records\n",
      "    return _fixed_getinnerframes(etb, number_of_lines_of_context, tb_offset)\n",
      "  File \"C:\\Users\\USER\\Anaconda3\\lib\\site-packages\\IPython\\core\\ultratb.py\", line 319, in wrapped\n",
      "    return f(*args, **kwargs)\n",
      "  File \"C:\\Users\\USER\\Anaconda3\\lib\\site-packages\\IPython\\core\\ultratb.py\", line 353, in _fixed_getinnerframes\n",
      "    records = fix_frame_records_filenames(inspect.getinnerframes(etb, context))\n",
      "  File \"C:\\Users\\USER\\Anaconda3\\lib\\inspect.py\", line 1502, in getinnerframes\n",
      "    frameinfo = (tb.tb_frame,) + getframeinfo(tb, context)\n",
      "  File \"C:\\Users\\USER\\Anaconda3\\lib\\inspect.py\", line 1460, in getframeinfo\n",
      "    filename = getsourcefile(frame) or getfile(frame)\n",
      "  File \"C:\\Users\\USER\\Anaconda3\\lib\\inspect.py\", line 696, in getsourcefile\n",
      "    if getattr(getmodule(object, filename), '__loader__', None) is not None:\n",
      "  File \"C:\\Users\\USER\\Anaconda3\\lib\\inspect.py\", line 733, in getmodule\n",
      "    if ismodule(module) and hasattr(module, '__file__'):\n",
      "  File \"C:\\Users\\USER\\Anaconda3\\lib\\site-packages\\tensorflow\\__init__.py\", line 50, in __getattr__\n",
      "    module = self._load()\n",
      "  File \"C:\\Users\\USER\\Anaconda3\\lib\\site-packages\\tensorflow\\__init__.py\", line 44, in _load\n",
      "    module = _importlib.import_module(self.__name__)\n",
      "  File \"C:\\Users\\USER\\Anaconda3\\lib\\importlib\\__init__.py\", line 127, in import_module\n",
      "    return _bootstrap._gcd_import(name[level:], package, level)\n",
      "  File \"<frozen importlib._bootstrap>\", line 1006, in _gcd_import\n",
      "  File \"<frozen importlib._bootstrap>\", line 983, in _find_and_load\n",
      "  File \"<frozen importlib._bootstrap>\", line 965, in _find_and_load_unlocked\n",
      "ModuleNotFoundError: No module named 'tensorflow_core.estimator'\n"
     ]
    },
    {
     "ename": "NameError",
     "evalue": "name 'show' is not defined",
     "output_type": "error",
     "traceback": [
      "\u001b[1;31m---------------------------------------------------------------------------\u001b[0m"
     ]
    }
   ],
   "source": [
    "show(bad_param_vis[0])"
   ]
  },
  {
   "cell_type": "code",
   "execution_count": 25,
   "metadata": {},
   "outputs": [
    {
     "name": "stderr",
     "output_type": "stream",
     "text": [
      "ERROR:root:Internal Python error in the inspect module.\n",
      "Below is the traceback from this internal error.\n",
      "\n"
     ]
    },
    {
     "name": "stdout",
     "output_type": "stream",
     "text": [
      "Traceback (most recent call last):\n",
      "  File \"C:\\Users\\USER\\Anaconda3\\lib\\site-packages\\IPython\\core\\interactiveshell.py\", line 3325, in run_code\n",
      "    exec(code_obj, self.user_global_ns, self.user_ns)\n",
      "  File \"<ipython-input-25-08f20a606890>\", line 5, in <module>\n",
      "    no_transforms_vis = render.render_vis(model, objective, param_f, transforms=transforms, verbose=True, thresholds=(25, 75, 150, 300, 512), print_objectives=[content_obj, style_obj])[-1]\n",
      "NameError: name 'render' is not defined\n",
      "\n",
      "During handling of the above exception, another exception occurred:\n",
      "\n",
      "Traceback (most recent call last):\n",
      "  File \"C:\\Users\\USER\\Anaconda3\\lib\\site-packages\\IPython\\core\\interactiveshell.py\", line 2039, in showtraceback\n",
      "    stb = value._render_traceback_()\n",
      "AttributeError: 'NameError' object has no attribute '_render_traceback_'\n",
      "\n",
      "During handling of the above exception, another exception occurred:\n",
      "\n",
      "Traceback (most recent call last):\n",
      "  File \"C:\\Users\\USER\\Anaconda3\\lib\\site-packages\\IPython\\core\\ultratb.py\", line 1101, in get_records\n",
      "    return _fixed_getinnerframes(etb, number_of_lines_of_context, tb_offset)\n",
      "  File \"C:\\Users\\USER\\Anaconda3\\lib\\site-packages\\IPython\\core\\ultratb.py\", line 319, in wrapped\n",
      "    return f(*args, **kwargs)\n",
      "  File \"C:\\Users\\USER\\Anaconda3\\lib\\site-packages\\IPython\\core\\ultratb.py\", line 353, in _fixed_getinnerframes\n",
      "    records = fix_frame_records_filenames(inspect.getinnerframes(etb, context))\n",
      "  File \"C:\\Users\\USER\\Anaconda3\\lib\\inspect.py\", line 1502, in getinnerframes\n",
      "    frameinfo = (tb.tb_frame,) + getframeinfo(tb, context)\n",
      "  File \"C:\\Users\\USER\\Anaconda3\\lib\\inspect.py\", line 1460, in getframeinfo\n",
      "    filename = getsourcefile(frame) or getfile(frame)\n",
      "  File \"C:\\Users\\USER\\Anaconda3\\lib\\inspect.py\", line 696, in getsourcefile\n",
      "    if getattr(getmodule(object, filename), '__loader__', None) is not None:\n",
      "  File \"C:\\Users\\USER\\Anaconda3\\lib\\inspect.py\", line 733, in getmodule\n",
      "    if ismodule(module) and hasattr(module, '__file__'):\n",
      "  File \"C:\\Users\\USER\\Anaconda3\\lib\\site-packages\\tensorflow\\__init__.py\", line 50, in __getattr__\n",
      "    module = self._load()\n",
      "  File \"C:\\Users\\USER\\Anaconda3\\lib\\site-packages\\tensorflow\\__init__.py\", line 44, in _load\n",
      "    module = _importlib.import_module(self.__name__)\n",
      "  File \"C:\\Users\\USER\\Anaconda3\\lib\\importlib\\__init__.py\", line 127, in import_module\n",
      "    return _bootstrap._gcd_import(name[level:], package, level)\n",
      "  File \"<frozen importlib._bootstrap>\", line 1006, in _gcd_import\n",
      "  File \"<frozen importlib._bootstrap>\", line 983, in _find_and_load\n",
      "  File \"<frozen importlib._bootstrap>\", line 965, in _find_and_load_unlocked\n",
      "ModuleNotFoundError: No module named 'tensorflow_core.estimator'\n"
     ]
    },
    {
     "ename": "NameError",
     "evalue": "name 'render' is not defined",
     "output_type": "error",
     "traceback": [
      "\u001b[1;31m---------------------------------------------------------------------------\u001b[0m"
     ]
    }
   ],
   "source": [
    "param_f = lambda: style_transfer_param(content_image, style_image, decorrelate=False, fft=False)\n",
    "\n",
    "transforms = [] # specifying an empty array overrides default transformations\n",
    "\n",
    "no_transforms_vis = render.render_vis(model, objective, param_f, transforms=transforms, verbose=True, thresholds=(25, 75, 150, 300, 512), print_objectives=[content_obj, style_obj])[-1]"
   ]
  },
  {
   "cell_type": "code",
   "execution_count": 26,
   "metadata": {},
   "outputs": [
    {
     "name": "stderr",
     "output_type": "stream",
     "text": [
      "ERROR:root:Internal Python error in the inspect module.\n",
      "Below is the traceback from this internal error.\n",
      "\n"
     ]
    },
    {
     "name": "stdout",
     "output_type": "stream",
     "text": [
      "Traceback (most recent call last):\n",
      "  File \"C:\\Users\\USER\\Anaconda3\\lib\\site-packages\\IPython\\core\\interactiveshell.py\", line 3325, in run_code\n",
      "    exec(code_obj, self.user_global_ns, self.user_ns)\n",
      "  File \"<ipython-input-26-7c241151bf8a>\", line 1, in <module>\n",
      "    detail = no_transforms_vis[0][-75:, 125:200, ...] # just a manually selected part of the above visualization\n",
      "NameError: name 'no_transforms_vis' is not defined\n",
      "\n",
      "During handling of the above exception, another exception occurred:\n",
      "\n",
      "Traceback (most recent call last):\n",
      "  File \"C:\\Users\\USER\\Anaconda3\\lib\\site-packages\\IPython\\core\\interactiveshell.py\", line 2039, in showtraceback\n",
      "    stb = value._render_traceback_()\n",
      "AttributeError: 'NameError' object has no attribute '_render_traceback_'\n",
      "\n",
      "During handling of the above exception, another exception occurred:\n",
      "\n",
      "Traceback (most recent call last):\n",
      "  File \"C:\\Users\\USER\\Anaconda3\\lib\\site-packages\\IPython\\core\\ultratb.py\", line 1101, in get_records\n",
      "    return _fixed_getinnerframes(etb, number_of_lines_of_context, tb_offset)\n",
      "  File \"C:\\Users\\USER\\Anaconda3\\lib\\site-packages\\IPython\\core\\ultratb.py\", line 319, in wrapped\n",
      "    return f(*args, **kwargs)\n",
      "  File \"C:\\Users\\USER\\Anaconda3\\lib\\site-packages\\IPython\\core\\ultratb.py\", line 353, in _fixed_getinnerframes\n",
      "    records = fix_frame_records_filenames(inspect.getinnerframes(etb, context))\n",
      "  File \"C:\\Users\\USER\\Anaconda3\\lib\\inspect.py\", line 1502, in getinnerframes\n",
      "    frameinfo = (tb.tb_frame,) + getframeinfo(tb, context)\n",
      "  File \"C:\\Users\\USER\\Anaconda3\\lib\\inspect.py\", line 1460, in getframeinfo\n",
      "    filename = getsourcefile(frame) or getfile(frame)\n",
      "  File \"C:\\Users\\USER\\Anaconda3\\lib\\inspect.py\", line 696, in getsourcefile\n",
      "    if getattr(getmodule(object, filename), '__loader__', None) is not None:\n",
      "  File \"C:\\Users\\USER\\Anaconda3\\lib\\inspect.py\", line 733, in getmodule\n",
      "    if ismodule(module) and hasattr(module, '__file__'):\n",
      "  File \"C:\\Users\\USER\\Anaconda3\\lib\\site-packages\\tensorflow\\__init__.py\", line 50, in __getattr__\n",
      "    module = self._load()\n",
      "  File \"C:\\Users\\USER\\Anaconda3\\lib\\site-packages\\tensorflow\\__init__.py\", line 44, in _load\n",
      "    module = _importlib.import_module(self.__name__)\n",
      "  File \"C:\\Users\\USER\\Anaconda3\\lib\\importlib\\__init__.py\", line 127, in import_module\n",
      "    return _bootstrap._gcd_import(name[level:], package, level)\n",
      "  File \"<frozen importlib._bootstrap>\", line 1006, in _gcd_import\n",
      "  File \"<frozen importlib._bootstrap>\", line 983, in _find_and_load\n",
      "  File \"<frozen importlib._bootstrap>\", line 965, in _find_and_load_unlocked\n",
      "ModuleNotFoundError: No module named 'tensorflow_core.estimator'\n"
     ]
    },
    {
     "ename": "NameError",
     "evalue": "name 'no_transforms_vis' is not defined",
     "output_type": "error",
     "traceback": [
      "\u001b[1;31m---------------------------------------------------------------------------\u001b[0m"
     ]
    }
   ],
   "source": [
    "detail = no_transforms_vis[0][-75:, 125:200, ...] # just a manually selected part of the above visualization\n",
    "zoomed4x = np.kron(detail, np.ones((4,4,1)))\n",
    "show(zoomed4x)"
   ]
  },
  {
   "cell_type": "code",
   "execution_count": null,
   "metadata": {},
   "outputs": [],
   "source": []
  }
 ],
 "metadata": {
  "kernelspec": {
   "display_name": "Python 3",
   "language": "python",
   "name": "python3"
  },
  "language_info": {
   "codemirror_mode": {
    "name": "ipython",
    "version": 3
   },
   "file_extension": ".py",
   "mimetype": "text/x-python",
   "name": "python",
   "nbconvert_exporter": "python",
   "pygments_lexer": "ipython3",
   "version": "3.7.3"
  }
 },
 "nbformat": 4,
 "nbformat_minor": 2
}
